Workbook
Name lstPriority: Lists!$B$2:$B$4
Name lstStatus: Lists!$A$2:$A$5
Name Slicer_Status: #N/A

Sheet Dashboard
A1: BU2 Ticket Dashboard
A3: Total tickets | B3: =COUNTA(tblTickets[Ticket ID]) -> 60
A4: Open tickets | B4: =COUNTIF(tblTickets[Status],"<>Closed") -> 39
A5: Open & SLA breached | B5: =COUNTIFS(tblTickets[Status],"<>Closed",tblTickets[SLA Status],"Breached") -> 29
A8: Count of Ticket ID | B8: Column Labels
A9: Row Labels | B9: Breached | C9: OK | D9: Grand Total
A10: Critical: quality and delivery | B10: 7 | C10: 6 | D10: 13
A11: Delivery risk | B11: 5 | C11: 1 | D11: 6
A12: Quality risk | B12: 5 | C12: 1 | D12: 6
A13: Reliable, lower spend | B13: 5 | C13: 1 | D13: 6
A14: Strategic and reliable | B14: 7 | C14: 1 | D14: 8
A15: Grand Total | B15: 29 | C15: 10 | D15: 39

Sheet Tickets
A1: Ticket ID | B1: Created On | C1: System | D1: Record ID | E1: Supplier | F1: Field | G1: DQ Dimension | H1: Issue | I1: Suggested Action | J1: Priority | K1: Status | L1: Owner | M1: Closed On | N1: Segment | O1: Age (days) | P1: SLA (days) | Q1: SLA Status
A2: T-0001 | B2: 46294 | C2: ERP_B | D2: SUP-0065 | E2: Kappaplast | F2: vat_number | G2: consistency | H2: VAT ID contains spaces | I2: Remove spaces during migration | J2: Low | K2: Closed | L2: S. Kaya | M2: 46300 | N2: =_xlfn.XLOOKUP(tblTickets[[#This Row],[Record ID]],Suppliers!A:A,Suppliers!E:E,"Not found") -> Critical: quality and delivery | O2: =IF(tblTickets[[#This Row],[Closed On]]="",TODAY()-tblTickets[[#This Row],[Created On]],tblTickets[[#This Row],[Closed On]]-tblTickets[[#This Row],[Created On]]) -> 6 | P2: =_xlfn.XLOOKUP(tblTickets[[#This Row],[Priority]],Lists!B:B,Lists!C:C) -> 20 | Q2: =IF(tblTickets[[#This Row],[Age (days)]]>tblTickets[[#This Row],[SLA (days)]],"Breached","OK") -> OK
A3: T-0002 | B3: 46298 | C3: ERP_B | D3: SUP-0057 | E3: Boratronic SAS | F3: vat_number | G3: consistency | H3: VAT ID contains spaces | I3: Remove spaces during migration | J3: Low | K3: Closed | L3: L. Rossi | M3: 46300 | N3: =_xlfn.XLOOKUP(tblTickets[[#This Row],[Record ID]],Suppliers!A:A,Suppliers!E:E,"Not found") -> Strategic and reliable | O3: =IF(tblTickets[[#This Row],[Closed On]]="",TODAY()-tblTickets[[#This Row],[Created On]],tblTickets[[#This Row],[Closed On]]-tblTickets[[#This Row],[Created On]]) -> 2 | P3: =_xlfn.XLOOKUP(tblTickets[[#This Row],[Priority]],Lists!B:B,Lists!C:C) -> 20 | Q3: =IF(tblTickets[[#This Row],[Age (days)]]>tblTickets[[#This Row],[SLA (days)]],"Breached","OK") -> OK
A4: T-0003 | B4: 46298 | C4: ERP_B | D4: SUP-0047 | E4: LUMENWERK S.R.O. | F4: vat_number | G4: consistency | H4: VAT ID contains spaces | I4: Remove spaces during migration | J4: Low | K4: In Progress | L4: J. Novak | N4: =_xlfn.XLOOKUP(tblTickets[[#This Row],[Record ID]],Suppliers!A:A,Suppliers!E:E,"Not found") -> Critical: quality and delivery | O4: =IF(tblTickets[[#This Row],[Closed On]]="",TODAY()-tblTickets[[#This Row],[Created On]],tblTickets[[#This Row],[Closed On]]-tblTickets[[#This Row],[Created On]]) -> 2 | P4: =_xlfn.XLOOKUP(tblTickets[[#This Row],[Priority]],Lists!B:B,Lists!C:C) -> 20 | Q4: =IF(tblTickets[[#This Row],[Age (days)]]>tblTickets[[#This Row],[SLA (days)]],"Breached","OK") -> OK
A5: T-0004 | B5: 46277 | C5: ERP_B | D5: SUP-0042 | E5: Voltawerk | F5: country | G5: consistency | H5: Country is not a standard English name / ISO code | I5: Map to ISO code DE | J5: Medium | K5: Open | L5: M. Chen | N5: =_xlfn.XLOOKUP(tblTickets[[#This Row],[Record ID]],Suppliers!A:A,Suppliers!E:E,"Not found") -> Critical: quality and delivery | O5: =IF(tblTickets[[#This Row],[Closed On]]="",TODAY()-tblTickets[[#This Row],[Created On]],tblTickets[[#This Row],[Closed On]]-tblTickets[[#This Row],[Created On]]) -> 23 | P5: =_xlfn.XLOOKUP(tblTickets[[#This Row],[Priority]],Lists!B:B,Lists!C:C) -> 10 | Q5: =IF(tblTickets[[#This Row],[Age (days)]]>tblTickets[[#This Row],[SLA (days)]],"Breached","OK") -> Breached
A6: T-0005 | B6: 46275 | C6: ERP_B | D6: SUP-0016 | E6: CERROCAST S.R.O. | F6: vat_number | G6: consistency | H6: VAT ID contains spaces | I6: Remove spaces during migration | J6: Low | K6: Open | L6: A. Weber | N6: =_xlfn.XLOOKUP(tblTickets[[#This Row],[Record ID]],Suppliers!A:A,Suppliers!E:E,"Not found") -> Critical: quality and delivery | O6: =IF(tblTickets[[#This Row],[Closed On]]="",TODAY()-tblTickets[[#This Row],[Created On]],tblTickets[[#This Row],[Closed On]]-tblTickets[[#This Row],[Created On]]) -> 25 | P6: =_xlfn.XLOOKUP(tblTickets[[#This Row],[Priority]],Lists!B:B,Lists!C:C) -> 20 | Q6: =IF(tblTickets[[#This Row],[Age (days)]]>tblTickets[[#This Row],[SLA (days)]],"Breached","OK") -> Breached
A7: T-0006 | B7: 46291 | C7: ERP_B | D7: SUP-0018 | E7: Atlaswerk | F7: vat_number | G7: consistency | H7: VAT ID contains spaces | I7: Remove spaces during migration | J7: Low | K7: Closed | L7: L. Rossi | M7: 46300 | N7: =_xlfn.XLOOKUP(tblTickets[[#This Row],[Record ID]],Suppliers!A:A,Suppliers!E:E,"Not found") -> Delivery risk | O7: =IF(tblTickets[[#This Row],[Closed On]]="",TODAY()-tblTickets[[#This Row],[Created On]],tblTickets[[#This Row],[Closed On]]-tblTickets[[#This Row],[Created On]]) -> 9 | P7: =_xlfn.XLOOKUP(tblTickets[[#This Row],[Priority]],Lists!B:B,Lists!C:C) -> 20 | Q7: =IF(tblTickets[[#This Row],[Age (days)]]>tblTickets[[#This Row],[SLA (days)]],"Breached","OK") -> OK
A8: T-0007 | B8: 46266 | C8: ERP_B | D8: SUP-0019 | E8: Nordplast s.r.o. | F8: vat_number | G8: consistency | H8: VAT ID contains spaces | I8: Remove spaces during migration | J8: Low | K8: Closed | L8: A. Weber | M8: 46268 | N8: =_xlfn.XLOOKUP(tblTickets[[#This Row],[Record ID]],Suppliers!A:A,Suppliers!E:E,"Not found") -> Delivery risk | O8: =IF(tblTickets[[#This Row],[Closed On]]="",TODAY()-tblTickets[[#This Row],[Created On]],tblTickets[[#This Row],[Closed On]]-tblTickets[[#This Row],[Created On]]) -> 2 | P8: =_xlfn.XLOOKUP(tblTickets[[#This Row],[Priority]],Lists!B:B,Lists!C:C) -> 20 | Q8: =IF(tblTickets[[#This Row],[Age (days)]]>tblTickets[[#This Row],[SLA (days)]],"Breached","OK") -> OK
A9: T-0008 | B9: 46268 | C9: ERP_B | D9: SUP-0027 | E9: Nordguss | F9: vat_number | G9: consistency | H9: VAT ID contains spaces | I9: Remove spaces during migration | J9: Low | K9: Open | L9: L. Rossi | N9: =_xlfn.XLOOKUP(tblTickets[[#This Row],[Record ID]],Suppliers!A:A,Suppliers!E:E,"Not found") -> Reliable, lower spend | O9: =IF(tblTickets[[#This Row],[Closed On]]="",TODAY()-tblTickets[[#This Row],[Created On]],tblTickets[[#This Row],[Closed On]]-tblTickets[[#This Row],[Created On]]) -> 32 | P9: =_xlfn.XLOOKUP(tblTickets[[#This Row],[Priority]],Lists!B:B,Lists!C:C) -> 20 | Q9: =IF(tblTickets[[#This Row],[Age (days)]]>tblTickets[[#This Row],[SLA (days)]],"Breached","OK") -> Breached
A10: T-0009 | B10: 46267 | C10: ERP_B | D10: SUP-0034 | E10: Primaplast | F10: vat_number | G10: consistency | H10: VAT ID contains spaces | I10: Remove spaces during migration | J10: Low | K10: Closed | L10: S. Kaya | M10: 46273 | N10: =_xlfn.XLOOKUP(tblTickets[[#This Row],[Record ID]],Suppliers!A:A,Suppliers!E:E,"Not found") -> Quality risk | O10: =IF(tblTickets[[#This Row],[Closed On]]="",TODAY()-tblTickets[[#This Row],[Created On]],tblTickets[[#This Row],[Closed On]]-tblTickets[[#This Row],[Created On]]) -> 6 | P10: =_xlfn.XLOOKUP(tblTickets[[#This Row],[Priority]],Lists!B:B,Lists!C:C) -> 20 | Q10: =IF(tblTickets[[#This Row],[Age (days)]]>tblTickets[[#This Row],[SLA (days)]],"Breached","OK") -> OK
A11: T-0010 | B11: 46278 | C11: ERP_B | D11: SUP-0032 | E11: Velawek s.r.o. | F11: vat_number | G11: consistency | H11: VAT ID contains spaces | I11: Remove spaces during migration | J11: Low | K11: In Progress | L11: M. Chen | N11: =_xlfn.XLOOKUP(tblTickets[[#This Row],[Record ID]],Suppliers!A:A,Suppliers!E:E,"Not found") -> Strategic and reliable | O11: =IF(tblTickets[[#This Row],[Closed On]]="",TODAY()-tblTickets[[#This Row],[Created On]],tblTickets[[#This Row],[Closed On]]-tblTickets[[#This Row],[Created On]]) -> 22 | P11: =_xlfn.XLOOKUP(tblTickets[[#This Row],[Priority]],Lists!B:B,Lists!C:C) -> 20 | Q11: =IF(tblTickets[[#This Row],[Age (days)]]>tblTickets[[#This Row],[SLA (days)]],"Breached","OK") -> Breached
A12: T-0011 | B12: 46297 | C12: ERP_B | D12: SUP-0055 | E12: Aquaparts GmbH | F12: vat_number | G12: consistency | H12: VAT ID contains spaces | I12: Remove spaces during migration | J12: Low | K12: Open | L12: A. Weber | N12: =_xlfn.XLOOKUP(tblTickets[[#This Row],[Record ID]],Suppliers!A:A,Suppliers!E:E,"Not found") -> Critical: quality and delivery | O12: =IF(tblTickets[[#This Row],[Closed On]]="",TODAY()-tblTickets[[#This Row],[Created On]],tblTickets[[#This Row],[Closed On]]-tblTickets[[#This Row],[Created On]]) -> 3 | P12: =_xlfn.XLOOKUP(tblTickets[[#This Row],[Priority]],Lists!B:B,Lists!C:C) -> 20 | Q12: =IF(tblTickets[[#This Row],[Age (days)]]>tblTickets[[#This Row],[SLA (days)]],"Breached","OK") -> OK
A13: T-0012 | B13: 46295 | C13: ERP_B | D13: SUP-0074 | E13: Silbercast GmbH | F13: vat_number | G13: consistency | H13: VAT ID contains spaces | I13: Remove spaces during migration | J13: Low | K13: Closed | L13: J. Novak | M13: 46300 | N13: =_xlfn.XLOOKUP(tblTickets[[#This Row],[Record ID]],Suppliers!A:A,Suppliers!E:E,"Not found") -> Reliable, lower spend | O13: =IF(tblTickets[[#This Row],[Closed On]]="",TODAY()-tblTickets[[#This Row],[Created On]],tblTickets[[#This Row],[Closed On]]-tblTickets[[#This Row],[Created On]]) -> 5 | P13: =_xlfn.XLOOKUP(tblTickets[[#This Row],[Priority]],Lists!B:B,Lists!C:C) -> 20 | Q13: =IF(tblTickets[[#This Row],[Age (days)]]>tblTickets[[#This Row],[SLA (days)]],"Breached","OK") -> OK
A14: T-0013 | B14: 46271 | C14: ERP_B | D14: SUP-0025 | E14: Rheinmeal s.r.o. | F14: vat_number | G14: consistency | H14: VAT ID contains spaces | I14: Remove spaces during migration | J14: Low | K14: Closed | L14: L. Rossi | M14: 46277 | N14: =_xlfn.XLOOKUP(tblTickets[[#This Row],[Record ID]],Suppliers!A:A,Suppliers!E:E,"Not found") -> Reliable, lower spend | O14: =IF(tblTickets[[#This Row],[Closed On]]="",TODAY()-tblTickets[[#This Row],[Created On]],tblTickets[[#This Row],[Closed On]]-tblTickets[[#This Row],[Created On]]) -> 6 | P14: =_xlfn.XLOOKUP(tblTickets[[#This Row],[Priority]],Lists!B:B,Lists!C:C) -> 20 | Q14: =IF(tblTickets[[#This Row],[Age (days)]]>tblTickets[[#This Row],[SLA (days)]],"Breached","OK") -> OK
A15: T-0014 | B15: 46298 | C15: ERP_B | D15: SUP-0006 | E15: Vltatronic Sp. z o.o. | F15: country | G15: consistency | H15: Country is not a standard English name / ISO code | I15: Map to ISO code PL | J15: Medium | K15: In Progress | L15: A. Weber | N15: =_xlfn.XLOOKUP(tblTickets[[#This Row],[Record ID]],Suppliers!A:A,Suppliers!E:E,"Not found") -> Critical: quality and delivery | O15: =IF(tblTickets[[#This Row],[Closed On]]="",TODAY()-tblTickets[[#This Row],[Created On]],tblTickets[[#This Row],[Closed On]]-tblTickets[[#This Row],[Created On]]) -> 2 | P15: =_xlfn.XLOOKUP(tblTickets[[#This Row],[Priority]],Lists!B:B,Lists!C:C) -> 10 | Q15: =IF(tblTickets[[#This Row],[Age (days)]]>tblTickets[[#This Row],[SLA (days)]],"Breached","OK") -> OK
A16: T-0015 | B16: 46272 | C16: ERP_B | D16: SUP-0060 | E16: KRAFTFORM SAS | F16: vat_number | G16: consistency | H16: VAT ID contains spaces | I16: Remove spaces during migration | J16: Low | K16: In Progress | L16: M. Chen | N16: =_xlfn.XLOOKUP(tblTickets[[#This Row],[Record ID]],Suppliers!A:A,Suppliers!E:E,"Not found") -> Quality risk | O16: =IF(tblTickets[[#This Row],[Closed On]]="",TODAY()-tblTickets[[#This Row],[Created On]],tblTickets[[#This Row],[Closed On]]-tblTickets[[#This Row],[Created On]]) -> 28 | P16: =_xlfn.XLOOKUP(tblTickets[[#This Row],[Priority]],Lists!B:B,Lists!C:C) -> 20 | Q16: =IF(tblTickets[[#This Row],[Age (days)]]>tblTickets[[#This Row],[SLA (days)]],"Breached","OK") -> Breached
A17: T-0016 | B17: 46290 | C17: ERP_B | D17: SUP-0056 | E17: Teraplast GmbH | F17: vat_number | G17: consistency | H17: VAT ID contains spaces | I17: Remove spaces during migration | J17: Low | K17: Open | L17: A. Weber | N17: =_xlfn.XLOOKUP(tblTickets[[#This Row],[Record ID]],Suppliers!A:A,Suppliers!E:E,"Not found") -> Delivery risk | O17: =IF(tblTickets[[#This Row],[Closed On]]="",TODAY()-tblTickets[[#This Row],[Created On]],tblTickets[[#This Row],[Closed On]]-tblTickets[[#This Row],[Created On]]) -> 10 | P17: =_xlfn.XLOOKUP(tblTickets[[#This Row],[Priority]],Lists!B:B,Lists!C:C) -> 20 | Q17: =IF(tblTickets[[#This Row],[Age (days)]]>tblTickets[[#This Row],[SLA (days)]],"Breached","OK") -> OK
A18: T-0017 | B18: 46266 | C18: ERP_B | D18: SUP-0012 | E18: Boracast GmbH | F18: vat_number | G18: consistency | H18: VAT ID contains spaces | I18: Remove spaces during migration | J18: Low | K18: Open | L18: A. Weber | N18: =_xlfn.XLOOKUP(tblTickets[[#This Row],[Record ID]],Suppliers!A:A,Suppliers!E:E,"Not found") -> Reliable, lower spend | O18: =IF(tblTickets[[#This Row],[Closed On]]="",TODAY()-tblTickets[[#This Row],[Created On]],tblTickets[[#This Row],[Closed On]]-tblTickets[[#This Row],[Created On]]) -> 34 | P18: =_xlfn.XLOOKUP(tblTickets[[#This Row],[Priority]],Lists!B:B,Lists!C:C) -> 20 | Q18: =IF(tblTickets[[#This Row],[Age (days)]]>tblTickets[[#This Row],[SLA (days)]],"Breached","OK") -> Breached
A19: T-0018 | B19: 46296 | C19: ERP_B | D19: SUP-0001 | E19: FERROMETAL GMBH | F19: vat_number | G19: consistency | H19: VAT ID contains spaces | I19: Remove spaces during migration | J19: Low | K19: In Progress | L19: S. Kaya | N19: =_xlfn.XLOOKUP(tblTickets[[#This Row],[Record ID]],Suppliers!A:A,Suppliers!E:E,"Not found") -> Strategic and reliable | O19: =IF(tblTickets[[#This Row],[Closed On]]="",TODAY()-tblTickets[[#This Row],[Created On]],tblTickets[[#This Row],[Closed On]]-tblTickets[[#This Row],[Created On]]) -> 4 | P19: =_xlfn.XLOOKUP(tblTickets[[#This Row],[Priority]],Lists!B:B,Lists!C:C) -> 20 | Q19: =IF(tblTickets[[#This Row],[Age (days)]]>tblTickets[[#This Row],[SLA (days)]],"Breached","OK") -> OK
A20: T-0019 | B20: 46292 | C20: ERP_B | D20: SUP-0008 | E20: KRAFTGUSS S.R.O. | F20: vat_number | G20: consistency | H20: VAT ID contains spaces | I20: Remove spaces during migration | J20: Low | K20: Open | L20: L. Rossi | N20: =_xlfn.XLOOKUP(tblTickets[[#This Row],[Record ID]],Suppliers!A:A,Suppliers!E:E,"Not found") -> Critical: quality and delivery | O20: =IF(tblTickets[[#This Row],[Closed On]]="",TODAY()-tblTickets[[#This Row],[Created On]],tblTickets[[#This Row],[Closed On]]-tblTickets[[#This Row],[Created On]]) -> 8 | P20: =_xlfn.XLOOKUP(tblTickets[[#This Row],[Priority]],Lists!B:B,Lists!C:C) -> 20 | Q20: =IF(tblTickets[[#This Row],[Age (days)]]>tblTickets[[#This Row],[SLA (days)]],"Breached","OK") -> OK
A21: T-0020 | B21: 46283 | C21: ERP_B | D21: SUP-0005 | E21: Ferrocast GmbH | F21: country | G21: consistency | H21: Country is not a standard English name / ISO code | I21: Map to ISO code DE | J21: Medium | K21: In Progress | L21: M. Chen | N21: =_xlfn.XLOOKUP(tblTickets[[#This Row],[Record ID]],Suppliers!A:A,Suppliers!E:E,"Not found") -> Quality risk | O21: =IF(tblTickets[[#This Row],[Closed On]]="",TODAY()-tblTickets[[#This Row],[Created On]],tblTickets[[#This Row],[Closed On]]-tblTickets[[#This Row],[Created On]]) -> 17 | P21: =_xlfn.XLOOKUP(tblTickets[[#This Row],[Priority]],Lists!B:B,Lists!C:C) -> 10 | Q21: =IF(tblTickets[[#This Row],[Age (days)]]>tblTickets[[#This Row],[SLA (days)]],"Breached","OK") -> Breached
A22: T-0021 | B22: 46287 | C22: ERP_B | D22: SUP-0039 | E22: Atlastronc GmbH | F22: vat_number | G22: consistency | H22: VAT ID contains spaces | I22: Remove spaces during migration | J22: Low | K22: Open | L22: S. Kaya | N22: =_xlfn.XLOOKUP(tblTickets[[#This Row],[Record ID]],Suppliers!A:A,Suppliers!E:E,"Not found") -> Reliable, lower spend | O22: =IF(tblTickets[[#This Row],[Closed On]]="",TODAY()-tblTickets[[#This Row],[Created On]],tblTickets[[#This Row],[Closed On]]-tblTickets[[#This Row],[Created On]]) -> 13 | P22: =_xlfn.XLOOKUP(tblTickets[[#This Row],[Priority]],Lists!B:B,Lists!C:C) -> 20 | Q22: =IF(tblTickets[[#This Row],[Age (days)]]>tblTickets[[#This Row],[SLA (days)]],"Breached","OK") -> OK
A23: T-0022 | B23: 46273 | C23: ERP_B | D23: SUP-0040 | E23: Ventoguss | F23: vat_number | G23: consistency | H23: VAT ID contains spaces | I23: Remove spaces during migration | J23: Low | K23: Open | L23: A. Weber | N23: =_xlfn.XLOOKUP(tblTickets[[#This Row],[Record ID]],Suppliers!A:A,Suppliers!E:E,"Not found") -> Critical: quality and delivery | O23: =IF(tblTickets[[#This Row],[Closed On]]="",TODAY()-tblTickets[[#This Row],[Created On]],tblTickets[[#This Row],[Closed On]]-tblTickets[[#This Row],[Created On]]) -> 27 | P23: =_xlfn.XLOOKUP(tblTickets[[#This Row],[Priority]],Lists!B:B,Lists!C:C) -> 20 | Q23: =IF(tblTickets[[#This Row],[Age (days)]]>tblTickets[[#This Row],[SLA (days)]],"Breached","OK") -> Breached
A24: T-0023 | B24: 46266 | C24: ERP_B | D24: SUP-0058 | E24: Deltaflex Sp. z o.o. | F24: vat_number | G24: consistency | H24: VAT ID contains spaces | I24: Remove spaces during migration | J24: Low | K24: Open | L24: S. Kaya | N24: =_xlfn.XLOOKUP(tblTickets[[#This Row],[Record ID]],Suppliers!A:A,Suppliers!E:E,"Not found") -> Delivery risk | O24: =IF(tblTickets[[#This Row],[Closed On]]="",TODAY()-tblTickets[[#This Row],[Created On]],tblTickets[[#This Row],[Closed On]]-tblTickets[[#This Row],[Created On]]) -> 34 | P24: =_xlfn.XLOOKUP(tblTickets[[#This Row],[Priority]],Lists!B:B,Lists!C:C) -> 20 | Q24: =IF(tblTickets[[#This Row],[Age (days)]]>tblTickets[[#This Row],[SLA (days)]],"Breached","OK") -> Breached
A25: T-0024 | B25: 46277 | C25: ERP_B | D25: SUP-0024 | E25: Velacast GmbH | F25: vat_number | G25: consistency | H25: VAT ID contains spaces | I25: Remove spaces during migration | J25: Low | K25: Closed | L25: S. Kaya | M25: 46281 | N25: =_xlfn.XLOOKUP(tblTickets[[#This Row],[Record ID]],Suppliers!A:A,Suppliers!E:E,"Not found") -> Strategic and reliable | O25: =IF(tblTickets[[#This Row],[Closed On]]="",TODAY()-tblTickets[[#This Row],[Created On]],tblTickets[[#This Row],[Closed On]]-tblTickets[[#This Row],[Created On]]) -> 4 | P25: =_xlfn.XLOOKUP(tblTickets[[#This Row],[Priority]],Lists!B:B,Lists!C:C) -> 20 | Q25: =IF(tblTickets[[#This Row],[Age (days)]]>tblTickets[[#This Row],[SLA (days)]],"Breached","OK") -> OK
A26: T-0025 | B26: 46298 | C26: ERP_B | D26: SUP-0069 | E26: Kraftflex | F26: vat_number | G26: consistency | H26: VAT ID contains spaces | I26: Remove spaces during migration | J26: Low | K26: Open | L26: L. Rossi | N26: =_xlfn.XLOOKUP(tblTickets[[#This Row],[Record ID]],Suppliers!A:A,Suppliers!E:E,"Not found") -> Critical: quality and delivery | O26: =IF(tblTickets[[#This Row],[Closed On]]="",TODAY()-tblTickets[[#This Row],[Created On]],tblTickets[[#This Row],[Closed On]]-tblTickets[[#This Row],[Created On]]) -> 2 | P26: =_xlfn.XLOOKUP(tblTickets[[#This Row],[Priority]],Lists!B:B,Lists!C:C) -> 20 | Q26: =IF(tblTickets[[#This Row],[Age (days)]]>tblTickets[[#This Row],[SLA (days)]],"Breached","OK") -> OK
A27: T-0026 | B27: 46292 | C27: ERP_A | D27: 0000100055 | E27: Deltaplast GmbH | F27: terms | G27: completeness | H27: Mandatory field 'terms' is empty | I27: Request value from supplier / purchasing | J27: Medium | K27: Closed | L27: S. Kaya | M27: 46294 | N27: =_xlfn.XLOOKUP(tblTickets[[#This Row],[Record ID]],Suppliers!A:A,Suppliers!E:E,"Not found") -> Reliable, lower spend | O27: =IF(tblTickets[[#This Row],[Closed On]]="",TODAY()-tblTickets[[#This Row],[Created On]],tblTickets[[#This Row],[Closed On]]-tblTickets[[#This Row],[Created On]]) -> 2 | P27: =_xlfn.XLOOKUP(tblTickets[[#This Row],[Priority]],Lists!B:B,Lists!C:C) -> 10 | Q27: =IF(tblTickets[[#This Row],[Age (days)]]>tblTickets[[#This Row],[SLA (days)]],"Breached","OK") -> OK
A28: T-0027 | B28: 46292 | C28: ERP_A | D28: 0000100186 | E28: Alpentronic GmbH | F28: vat | G28: completeness | H28: Mandatory field 'vat' is empty | I28: Request value from supplier / purchasing | J28: High | K28: Closed | L28: M. Chen | M28: 46293 | N28: =_xlfn.XLOOKUP(tblTickets[[#This Row],[Record ID]],Suppliers!A:A,Suppliers!E:E,"Not found") -> Strategic and reliable | O28: =IF(tblTickets[[#This Row],[Closed On]]="",TODAY()-tblTickets[[#This Row],[Created On]],tblTickets[[#This Row],[Closed On]]-tblTickets[[#This Row],[Created On]]) -> 1 | P28: =_xlfn.XLOOKUP(tblTickets[[#This Row],[Priority]],Lists!B:B,Lists!C:C) -> 5 | Q28: =IF(tblTickets[[#This Row],[Age (days)]]>tblTickets[[#This Row],[SLA (days)]],"Breached","OK") -> OK
A29: T-0028 | B29: 46285 | C29: ERP_A | D29: 0000100334 | E29: Lumencast GmbH | F29: iban | G29: completeness | H29: Mandatory field 'iban' is empty | I29: Request value from supplier / purchasing | J29: High | K29: Closed | L29: L. Rossi | M29: 46286 | N29: =_xlfn.XLOOKUP(tblTickets[[#This Row],[Record ID]],Suppliers!A:A,Suppliers!E:E,"Not found") -> Quality risk | O29: =IF(tblTickets[[#This Row],[Closed On]]="",TODAY()-tblTickets[[#This Row],[Created On]],tblTickets[[#This Row],[Closed On]]-tblTickets[[#This Row],[Created On]]) -> 1 | P29: =_xlfn.XLOOKUP(tblTickets[[#This Row],[Priority]],Lists!B:B,Lists!C:C) -> 5 | Q29: =IF(tblTickets[[#This Row],[Age (days)]]>tblTickets[[#This Row],[SLA (days)]],"Breached","OK") -> OK
A30: T-0029 | B30: 46277 | C30: ERP_A | D30: 0000100334 | E30: Lumencast GmbH | F30: terms | G30: completeness | H30: Mandatory field 'terms' is empty | I30: Request value from supplier / purchasing | J30: Medium | K30: In Progress | L30: J. Novak | N30: =_xlfn.XLOOKUP(tblTickets[[#This Row],[Record ID]],Suppliers!A:A,Suppliers!E:E,"Not found") -> Quality risk | O30: =IF(tblTickets[[#This Row],[Closed On]]="",TODAY()-tblTickets[[#This Row],[Created On]],tblTickets[[#This Row],[Closed On]]-tblTickets[[#This Row],[Created On]]) -> 23 | P30: =_xlfn.XLOOKUP(tblTickets[[#This Row],[Priority]],Lists!B:B,Lists!C:C) -> 10 | Q30: =IF(tblTickets[[#This Row],[Age (days)]]>tblTickets[[#This Row],[SLA (days)]],"Breached","OK") -> Breached
A31: T-0030 | B31: 46272 | C31: ERP_A | D31: 0000100247 | E31: Voltaflex GmbH | F31: vat | G31: completeness | H31: Mandatory field 'vat' is empty | I31: Request value from supplier / purchasing | J31: High | K31: Open | L31: L. Rossi | N31: =_xlfn.XLOOKUP(tblTickets[[#This Row],[Record ID]],Suppliers!A:A,Suppliers!E:E,"Not found") -> Delivery risk | O31: =IF(tblTickets[[#This Row],[Closed On]]="",TODAY()-tblTickets[[#This Row],[Created On]],tblTickets[[#This Row],[Closed On]]-tblTickets[[#This Row],[Created On]]) -> 28 | P31: =_xlfn.XLOOKUP(tblTickets[[#This Row],[Priority]],Lists!B:B,Lists!C:C) -> 5 | Q31: =IF(tblTickets[[#This Row],[Age (days)]]>tblTickets[[#This Row],[SLA (days)]],"Breached","OK") -> Breached
A32: T-0031 | B32: 46279 | C32: ERP_A | D32: 0000100168 | E32: Kraftseal S.r.l. | F32: iban | G32: completeness | H32: Mandatory field 'iban' is empty | I32: Request value from supplier / purchasing | J32: High | K32: In Progress | L32: A. Weber | N32: =_xlfn.XLOOKUP(tblTickets[[#This Row],[Record ID]],Suppliers!A:A,Suppliers!E:E,"Not found") -> Strategic and reliable | O32: =IF(tblTickets[[#This Row],[Closed On]]="",TODAY()-tblTickets[[#This Row],[Created On]],tblTickets[[#This Row],[Closed On]]-tblTickets[[#This Row],[Created On]]) -> 21 | P32: =_xlfn.XLOOKUP(tblTickets[[#This Row],[Priority]],Lists!B:B,Lists!C:C) -> 5 | Q32: =IF(tblTickets[[#This Row],[Age (days)]]>tblTickets[[#This Row],[SLA (days)]],"Breached","OK") -> Breached
A33: T-0032 | B33: 46287 | C33: ERP_A | D33: 0000100216 | E33: Alpenwerk GmbH | F33: terms | G33: completeness | H33: Mandatory field 'terms' is empty | I33: Request value from supplier / purchasing | J33: Medium | K33: Closed | L33: A. Weber | M33: 46294 | N33: =_xlfn.XLOOKUP(tblTickets[[#This Row],[Record ID]],Suppliers!A:A,Suppliers!E:E,"Not found") -> Quality risk | O33: =IF(tblTickets[[#This Row],[Closed On]]="",TODAY()-tblTickets[[#This Row],[Created On]],tblTickets[[#This Row],[Closed On]]-tblTickets[[#This Row],[Created On]]) -> 7 | P33: =_xlfn.XLOOKUP(tblTickets[[#This Row],[Priority]],Lists!B:B,Lists!C:C) -> 10 | Q33: =IF(tblTickets[[#This Row],[Age (days)]]>tblTickets[[#This Row],[SLA (days)]],"Breached","OK") -> OK
A34: T-0033 | B34: 46270 | C34: ERP_A | D34: 0000100367 | E34: Ferroparts GmbH | F34: vat | G34: validity | H34: VAT ID does not match the DE format | I34: Verify VAT ID (e.g. EU VIES check) | J34: High | K34: Open | L34: J. Novak | N34: =_xlfn.XLOOKUP(tblTickets[[#This Row],[Record ID]],Suppliers!A:A,Suppliers!E:E,"Not found") -> Strategic and reliable | O34: =IF(tblTickets[[#This Row],[Closed On]]="",TODAY()-tblTickets[[#This Row],[Created On]],tblTickets[[#This Row],[Closed On]]-tblTickets[[#This Row],[Created On]]) -> 30 | P34: =_xlfn.XLOOKUP(tblTickets[[#This Row],[Priority]],Lists!B:B,Lists!C:C) -> 5 | Q34: =IF(tblTickets[[#This Row],[Age (days)]]>tblTickets[[#This Row],[SLA (days)]],"Breached","OK") -> Breached
A35: T-0034 | B35: 46281 | C35: ERP_A | D35: 0000100153 | E35: Atlasplast Sp. z o.o. | F35: vat | G35: validity | H35: VAT ID does not match the PL format | I35: Verify VAT ID (e.g. EU VIES check) | J35: High | K35: Open | L35: M. Chen | N35: =_xlfn.XLOOKUP(tblTickets[[#This Row],[Record ID]],Suppliers!A:A,Suppliers!E:E,"Not found") -> Strategic and reliable | O35: =IF(tblTickets[[#This Row],[Closed On]]="",TODAY()-tblTickets[[#This Row],[Created On]],tblTickets[[#This Row],[Closed On]]-tblTickets[[#This Row],[Created On]]) -> 19 | P35: =_xlfn.XLOOKUP(tblTickets[[#This Row],[Priority]],Lists!B:B,Lists!C:C) -> 5 | Q35: =IF(tblTickets[[#This Row],[Age (days)]]>tblTickets[[#This Row],[SLA (days)]],"Breached","OK") -> Breached
A36: T-0035 | B36: 46289 | C36: ERP_A | D36: 0000100162 | E36: Tauroform Sp. z o.o. | F36: iban | G36: completeness | H36: Mandatory field 'iban' is empty | I36: Request value from supplier / purchasing | J36: High | K36: Waiting | L36: L. Rossi | N36: =_xlfn.XLOOKUP(tblTickets[[#This Row],[Record ID]],Suppliers!A:A,Suppliers!E:E,"Not found") -> Critical: quality and delivery | O36: =IF(tblTickets[[#This Row],[Closed On]]="",TODAY()-tblTickets[[#This Row],[Created On]],tblTickets[[#This Row],[Closed On]]-tblTickets[[#This Row],[Created On]]) -> 11 | P36: =_xlfn.XLOOKUP(tblTickets[[#This Row],[Priority]],Lists!B:B,Lists!C:C) -> 5 | Q36: =IF(tblTickets[[#This Row],[Age (days)]]>tblTickets[[#This Row],[SLA (days)]],"Breached","OK") -> Breached
A37: T-0036 | B37: 46296 | C37: ERP_A | D37: 0000100071 | E37: Cerrowerk Sp. z o.o. | F37: vat | G37: completeness | H37: Mandatory field 'vat' is empty | I37: Request value from supplier / purchasing | J37: High | K37: Closed | L37: S. Kaya | M37: 46299 | N37: =_xlfn.XLOOKUP(tblTickets[[#This Row],[Record ID]],Suppliers!A:A,Suppliers!E:E,"Not found") -> Delivery risk | O37: =IF(tblTickets[[#This Row],[Closed On]]="",TODAY()-tblTickets[[#This Row],[Created On]],tblTickets[[#This Row],[Closed On]]-tblTickets[[#This Row],[Created On]]) -> 3 | P37: =_xlfn.XLOOKUP(tblTickets[[#This Row],[Priority]],Lists!B:B,Lists!C:C) -> 5 | Q37: =IF(tblTickets[[#This Row],[Age (days)]]>tblTickets[[#This Row],[SLA (days)]],"Breached","OK") -> OK
A38: T-0037 | B38: 46277 | C38: ERP_A | D38: 0000100011 | E38: Novaform GmbH | F38: iban | G38: validity | H38: IBAN fails length or check-digit test | I38: Block payments until bank data is confirmed | J38: High | K38: Waiting | L38: M. Chen | N38: =_xlfn.XLOOKUP(tblTickets[[#This Row],[Record ID]],Suppliers!A:A,Suppliers!E:E,"Not found") -> Quality risk | O38: =IF(tblTickets[[#This Row],[Closed On]]="",TODAY()-tblTickets[[#This Row],[Created On]],tblTickets[[#This Row],[Closed On]]-tblTickets[[#This Row],[Created On]]) -> 23 | P38: =_xlfn.XLOOKUP(tblTickets[[#This Row],[Priority]],Lists!B:B,Lists!C:C) -> 5 | Q38: =IF(tblTickets[[#This Row],[Age (days)]]>tblTickets[[#This Row],[SLA (days)]],"Breached","OK") -> Breached
A39: T-0038 | B39: 46280 | C39: ERP_A | D39: 0000100387 | E39: Lumenparts GmbH | F39: vat | G39: completeness | H39: Mandatory field 'vat' is empty | I39: Request value from supplier / purchasing | J39: High | K39: Closed | L39: L. Rossi | M39: 46284 | N39: =_xlfn.XLOOKUP(tblTickets[[#This Row],[Record ID]],Suppliers!A:A,Suppliers!E:E,"Not found") -> Reliable, lower spend | O39: =IF(tblTickets[[#This Row],[Closed On]]="",TODAY()-tblTickets[[#This Row],[Created On]],tblTickets[[#This Row],[Closed On]]-tblTickets[[#This Row],[Created On]]) -> 4 | P39: =_xlfn.XLOOKUP(tblTickets[[#This Row],[Priority]],Lists!B:B,Lists!C:C) -> 5 | Q39: =IF(tblTickets[[#This Row],[Age (days)]]>tblTickets[[#This Row],[SLA (days)]],"Breached","OK") -> OK
A40: T-0039 | B40: 46276 | C40: ERP_A | D40: 0000100019 | E40: Ferrocast GmbH | F40: iban | G40: completeness | H40: Mandatory field 'iban' is empty | I40: Request value from supplier / purchasing | J40: High | K40: Closed | L40: L. Rossi | M40: 46285 | N40: =_xlfn.XLOOKUP(tblTickets[[#This Row],[Record ID]],Suppliers!A:A,Suppliers!E:E,"Not found") -> Quality risk | O40: =IF(tblTickets[[#This Row],[Closed On]]="",TODAY()-tblTickets[[#This Row],[Created On]],tblTickets[[#This Row],[Closed On]]-tblTickets[[#This Row],[Created On]]) -> 9 | P40: =_xlfn.XLOOKUP(tblTickets[[#This Row],[Priority]],Lists!B:B,Lists!C:C) -> 5 | Q40: =IF(tblTickets[[#This Row],[Age (days)]]>tblTickets[[#This Row],[SLA (days)]],"Breached","OK") -> Breached
...

Sheet Lists
A1: Status | B1: Priority | C1: SLA (days)
A2: Open | B2: High | C2: 5
A3: In Progress | B3: Medium | C3: 10
A4: Waiting | B4: Low | C4: 20
A5: Closed

Sheet About
A1: BU2 Ticket Tracker - Supplier master-data migration (practice file)
A2: Issues come from the M1 data-quality checks on a SYNTHETIC dataset.
A3: Created date, status, owner and closed date are simulated for the Excel exercises. Owners are fictional.

Sheet Suppliers
A1: Record ID | B1: System | C1: Golden ID | D1: Golden Name | E1: Segment
A2: 0000100055 | B2: ERP_A | C2: G0001 | D2: Deltaplast GmbH | E2: Reliable, lower spend
A3: 0000100254 | B3: ERP_A | C3: G0002 | D3: Ferroform s.r.o. | E3: Critical: quality and delivery
A4: SUP-0043 | B4: ERP_B | C4: G0002 | D4: Ferroform s.r.o. | E4: Critical: quality and delivery
A5: 0000100075 | B5: ERP_A | C5: G0003 | D5: Atlaswerk GmbH | E5: Delivery risk
A6: SUP-0018 | B6: ERP_B | C6: G0003 | D6: Atlaswerk GmbH | E6: Delivery risk
A7: 0000100099 | B7: ERP_A | C7: G0004 | D7: Ventoline S.r.l. | E7: Critical: quality and delivery
A8: SUP-0021 | B8: ERP_B | C8: G0004 | D8: Ventoline S.r.l. | E8: Critical: quality and delivery
A9: 0000100048 | B9: ERP_A | C9: G0005 | D9: Lumenflex SAS | E9: Delivery risk
A10: 0000100206 | B10: ERP_A | C10: G0006 | D10: Aquametal GmbH | E10: Delivery risk
A11: SUP-0036 | B11: ERP_B | C11: G0006 | D11: Aquametal GmbH | E11: Delivery risk
A12: 0000100046 | B12: ERP_A | C12: G0007 | D12: Orbiscast s.r.o. | E12: Critical: quality and delivery
... A165: SUP-0048 | B165: ERP_B | C165: G0120 | D165: Taurotec GmbH | E165: Strategic and reliable
